Workbook

Sheet Automation Monitoring
D1: Last Update 20 July 2026 16:25 WIB
B4: Project ID | C4: Application ID | D4: Nama Aplikasi | E4: Estimated / Total TC | F4: Final TC | G4: Done Scripting | I4: Done Running | K4: Timeline Scripting / Regression in Year 2024 | L4: Platform | M4: Pdf | N4: Git | O4: Excel | P4: Branch Git | Q4: PIC B2B | R4: PIC FTE | T4: Device | V4: Chart | AM4: Nama Aplikasi | AN4: Estimated / Total TC | AO4: Final TC | AP4: Done Scripting | AR4: Done Running | AU4: Nama Aplikasi | AV4: Estimated / Total TC | AW4: Final TC | AX4: Done Scripting | AZ4: Done Running | BC4: Nama Aplikasi | BD4: Estimated / Total TC | BE4: Final TC | BF4: Done Scripting | BH4: Done Running
G5: TC | H5: Percentage | I5: TC | J5: Percentage | S5: Tools Auto | AP5: TC | AQ5: Percentage | AR5: TC | AS5: Percentage | AX5: TC | AY5: Percentage | AZ5: TC | BA5: Percentage | BF5: TC | BG5: Percentage | BH5: TC | BI5: Percentage
B6: P24095 | C6: ABOAST0135 | D6: Integrated & Centralized Online System (ICONS)-Tokyo | E6: 1079 | F6: 1079 | G6: 1079 | H6: =G6/F6 -> 1 | I6: 1079 | J6: =I6/F6 -> 1 | K6: Aug-Sept | L6: Web | M6: https://bankbnitbk-my.sharepoint.com/:f:/g/personal/67063_hq_bni_co_id/EioRDAk7tqJPhuKwrES1L6wBVVJh6wJLeRC7QuskMdzpLg?e=NkMAm7 | N6: https://gitlab-dc.bni.co.id/marchy.tio/icons.git | P6: dev_tokyo_merge | S6: UFT​ | AM6: BNI Direct Reguler / Reskinning | AN6: 740 | AO6: 695 | AP6: 623 | AQ6: =AP6/AO6 -> 0.89640288 | AR6: 623 | AS6: =AR6/AO6 -> 0.89640288 | AU6: BNI Direct Reguler / Reskinning | AV6: 740 | AW6: 695 | AX6: 623 | AY6: =AX6/AW6 -> 0.89640288 | AZ6: 623 | BA6: =AZ6/AW6 -> 0.89640288 | BC6: ICONS Tokyo | BD6: 1079 | BE6: 1079 | BF6: 1079 | BG6: =BF6/BE6 -> 1 | BH6: 1079 | BI6: =BH6/BE6 -> 1
B7: P24095 | C7: ABOAST0141 | D7: Integrated & Centralized Online System (LDN)-London | E7: 1006 | F7: 1006 | G7: 699 | H7: =G7/F7 -> 0.69483101 | I7: =BH7 -> 694 | J7: =I7/F7 -> 0.68986083 | K7: Okt-Nov | L7: Web | M7: https://bankbnitbk-my.sharepoint.com/:f:/g/personal/67063_hq_bni_co_id/EuJYUqs4i9pFljj3tLIKD_ABTVsQGOw747c_n_zduBE5-w?e=ir28YJ | N7: https://gitlab-dc.bni.co.id/marchy.tio/icons.git | P7: dev_london_merge | S7: UFT​ | AM7: BNI Direct Lite | AN7: 1748 | AO7: 1603 | AP7: 917 | AQ7: =AP7/AO7 -> 0.5720524 | AR7: 917 | AS7: =AR7/AO7 -> 0.5720524 | AU7: CXO Onboarding | AV7: 443 | AW7: 397 | AX7: 397 | AY7: =AX7/AW7 -> 1 | AZ7: 397 | BA7: =AZ7/AW7 -> 1 | BC7: ICONS London | BD7: 1006 | BE7: 1006 | BF7: 699 | BG7: =BF7/BE7 -> 0.69483101 | BH7: 694 | BI7: =BH7/BE7 -> 0.68986083
B8: P24095 | C8: ABOAST0142 | D8: Integrated & Centralized Online System (NYA)-New York | E8: 1013 | F8: 1013 | G8: 573 | H8: =G8/F8 -> 0.56564659 | I8: 565 | J8: =I8/F8 -> 0.55774926 | K8: Nov | L8: Web | M8: https://bankbnitbk-my.sharepoint.com/:f:/g/personal/67063_hq_bni_co_id/EjVOeAe_2_dEsC8Zvi54WZsBpHAq_N1suUGmclnT87wPpw?e=rm3sTp | N8: https://gitlab-dc.bni.co.id/marchy.tio/icons.git | P8: dev_newyork_merge | S8: UFT​ | AM8: CXO Onboarding | AN8: 443 | AO8: 397 | AP8: 397 | AQ8: =AP8/AO8 -> 1 | AR8: 397 | AS8: =AR8/AO8 -> 1 | AU8: Ibank Remittance Fase 1 | AV8: 203 | AW8: 185 | AX8: 185 | AY8: =AX8/AW8 -> 1 | AZ8: 185 | BA8: =AZ8/AW8 -> 1 | BC8: ICONS New York | BD8: 1013 | BE8: 1013 | BF8: 573 | BG8: =BF8/BE8 -> 0.56564659 | BH8: 565 | BI8: =BH8/BE8 -> 0.55774926
B9: P24095 | C9: ABOAST0140 | D9: Integrated & Centralized Online System (HKG)-Hongkong | E9: 932 | F9: 932 | G9: 406 | H9: =G9/F9 -> 0.43562232 | I9: 406 | J9: =I9/F9 -> 0.43562232 | K9: Feb-Mar | L9: Web | M9: https://bankbnitbk-my.sharepoint.com/:f:/g/personal/67063_hq_bni_co_id/EhCZ_7N9tNJIgATRbmpYaiQBdeT1-CRl5iGafkKuKTPiZQ?e=zLjz5h | N9: https://gitlab-dc.bni.co.id/marchy.tio/icons.git | P9: dev_hongkong_merge | S9: UFT​
B10: P24095 | C10: ABOAST0143 | D10: Integrated & Centralized Online System (SEO)-Seoul | E10: 921 | F10: 921 | G10: 338 | H10: =G10/F10 -> 0.3669924 | I10: 338 | J10: =I10/F10 -> 0.3669924 | K10: Mar-Apr | L10: Web | M10: https://bankbnitbk-my.sharepoint.com/:f:/g/personal/67063_hq_bni_co_id/EsBNhr_IOGZFi183hsODeQkBtAeT1vSg7cuoGc_uC31tLA?e=lOMw0E | N10: https://gitlab-dc.bni.co.id/marchy.tio/icons.git | P10: dev_seoul_merge | S10: UFT​
B11: P24095 | C11: ABOAST0144 | D11: Integrated & Centralized Online System (SNG)-Singapore | E11: 918 | F11: 918 | G11: 424 | H11: =G11/F11 -> 0.46187364 | I11: 424 | J11: =I11/F11 -> 0.46187364 | K11: April | L11: Web | M11: https://bankbnitbk-my.sharepoint.com/:f:/g/personal/67063_hq_bni_co_id/EmPaCuMegxFFsa-ggkUGxqcB3ihP__H4lUFyGJj9DtT8wQ?e=UtXsow | N11: https://gitlab-dc.bni.co.id/marchy.tio/icons.git | P11: dev_singapore_merge | S11: UFT​
B12: P23055 | C12: ABOAST0135 | D12: Integrated & Centralized Online System (ICONS)-Poseidon | E12: =BD12 -> 1567 | F12: =BE12 -> 1554 | G12: =BF12 -> 1416 | H12: =G12/F12 -> 0.91119691 | I12: =BH12 -> 1416 | J12: =I12/F12 -> 0.91119691 | K12: Jan | L12: Web | N12: https://gitlab-dc.bni.co.id/marchy.tio/icons.git | P12: dev_alternity_merging | S12: UFT​ | AM12: Tiplus UFE | AN12: 299 | AO12: 252 | AP12: 252 | AQ12: =AP12/AO12 -> 1 | AR12: 252 | AS12: =AR12/AO12 -> 1 | AU12: Ibank Remittance Fase 2 | AV12: 481 | AW12: 457 | AX12: 457 | AY12: =AX12/AW12 -> 1 | AZ12: 457 | BA12: =AZ12/AW12 -> 1 | BC12: ICONS Poseidon | BD12: 1567 | BE12: 1554 | BF12: 1416 | BG12: =BF12/BE12 -> 0.91119691 | BH12: 1416 | BI12: =BH12/BE12 -> 0.91119691
B13: P24015 | C13: AFONFO0032 | D13: BNIDirect Cash Management-BNI Direct Reguler / Reskinning | E13: 763 | F13: 695 | G13: 623 | H13: =G13/F13 -> 0.89640288 | I13: 623 | J13: =I13/F13 -> 0.89640288 | K13: Jul-Nov | L13: Web | M13: https://bankbnitbk.sharepoint.com/:f:/s/TEST212/EjoE11ji--FKn_mAQAz4i8oBtXukZNAGOhwCVulYtzAAIw?e=yikl5b | N13: https://gitlab-dc.bni.co.id/coe-duplicate/test-automation/katalon-bni-direct-reguler.git | Q13: Aulia, Akbar | R13: Thomas | S13: Katalon​ | AM13: Tiplus SFE | AN13: 273 | AO13: 231 | AP13: 231 | AQ13: =AP13/AO13 -> 1 | AR13: 231 | AS13: =AR13/AO13 -> 1 | AU13: Ibank Remittance Fase 3 | AV13: 400 | AW13: 194 | AX13: 194 | AY13: =AX13/AW13 -> 1 | AZ13: 194 | BA13: =AZ13/AW13 -> 1 | BC13: Mobile Banking (Android) | BD13: 11180 | BE13: 1709 | BF13: 1709 | BG13: =BF13/BE13 -> 1 | BH13: 1709 | BI13: =BH13/BE13 -> 1
B14: P24015 | C14: AFONFO0032 | D14: BNIDirect Cash Management-BNI Direct Lite | E14: 1750 | F14: 1603 | G14: 917 | H14: =G14/F14 -> 0.5720524 | I14: 917 | J14: =I14/F14 -> 0.5720524 | K14: Jul-Oct | L14: Web | M14: https://bankbnitbk.sharepoint.com/:f:/s/TEST212/EpfIVe6XOoxBplTCYePMJa0BkxvW5XBagBxVsZQHZwJadQ?e=M35rtn | N14: https://gitlab-dc.bni.co.id/coe-duplicate/test-automation/katalon-bni-direct-lite.git | Q14: Aulia, Burhan | R14: Thomas | S14: Katalon​ | AM14: Tiplus Export Local | AN14: 522 | AO14: 133 | AP14: 0 | AQ14: =AP14/AO14 -> 0 | AR14: 0 | AS14: =AR14/AO14 -> 0 | AU14: Mobile Wondr Business (Android) | AV14: 732 | AW14: 93 | AX14: 80 | AY14: =AX14/AW14 -> 0.86021505 | AZ14: 80 | BA14: =AZ14/AX14 -> 1 | BC14: Mobile Banking (iOS) | BD14: 11180 | BE14: 1328 | BF14: 1328 | BG14: =BF14/BE14 -> 1 | BH14: 1328 | BI14: =BH14/BE14 -> 1
B15: P24015 | C15: AFONFO0175 | D15: BNIDirect Portal-CXO | E15: 1158 | F15: 896 | G15: 896 | H15: =G15/F15 -> 1 | I15: 896 | J15: =I15/F15 -> 1 | K15: Sep-Dec | L15: Web | M15: https://bankbnitbk.sharepoint.com/:f:/s/TEST212/EshJqUQ8NgtJrM1fA3NLjP0BPMd-vipEJVXTXkGsyi7Biw?e=EJxxfA | N15: https://gitlab-dc.bni.co.id/coe-duplicate/test-automation/katalon-cxo-onboarding.git | Q15: Gafi | R15: Thomas, Mbincar | S15: Katalon​ | AM15: Tiplus GB Local | AN15: 5264 | AO15: 5264 | AP15: 214 | AQ15: =AP15/AO15 -> 0.040653495 | AR15: 214 | AS15: =AR15/AO15 -> 0.040653495 | AU15: Mobile Wondr Business (iOS) | AV15: 732 | AW15: 92 | AX15: 92 | AY15: =AX15/AW15 -> 1 | AZ15: 74 | BA15: =AZ15/AX15 -> 0.80434783 | BC15: GB Online | BD15: 555 | BE15: 420 | BF15: 0 | BG15: =BF15/BE15 -> 0 | BH15: 0 | BI15: =BH15/BE15 -> 0
B16: P24016 | C16: ABOAST0245 | D16: TIPlus-Tiplus UFE | E16: 395 | F16: 312 | G16: 256 | H16: =G16/F16 -> 0.82051282 | I16: 256 | J16: =I16/F16 -> 0.82051282 | K16: Aug-Mar | L16: Web | M16: https://bankbnitbk.sharepoint.com/:f:/s/TEST212/El9fXPrW_0xEprlffGoewXkB11ZARqXcvZV5_6zbpZffWg?e=rrbDbV | N16: https://gitlab-dc.bni.co.id/coe-duplicate/test-automation/katalon-tiplus-ufe.git | Q16: Alkha, Andin | R16: Thomas | S16: Katalon​ | AM16: Ibank Remittance Fase 1 | AN16: 203 | AO16: 185 | AP16: 185 | AQ16: =AP16/AO16 -> 1 | AR16: 185 | AS16: =AR16/AO16 -> 1 | AU16: Mobile SMS Menu (Android) | AV16: 898 | AW16: 780 | AX16: 772 | AY16: =AX16/AW16 -> 0.98974359 | AZ16: 772 | BA16: =AZ16/AW16 -> 0.98974359
B17: P24016 | C17: ABOAST0245 | D17: TIPlus-Tiplus SFE | E17: 399 | F17: 318 | G17: 312 | H17: =G17/F17 -> 0.98113208 | I17: 312 | J17: =I17/F17 -> 0.98113208 | K17: Aug-Mar | L17: Web | M17: https://bankbnitbk.sharepoint.com/:f:/s/TEST212/Emapha_Bb-9DkeVfXC8xJYUBRyjYGeVp-Oe6NTAG5ipn9A?e=ONdMX9 | N17: https://gitlab-dc.bni.co.id/coe-duplicate/test-automation/katalon-tiplus-sfe.git | Q17: Andin | R17: Thomas | S17: Katalon​ | AM17: Ibank Remittance Fase 2 | AN17: 481 | AO17: 457 | AP17: 457 | AQ17: =AP17/AO17 -> 1 | AR17: 457 | AS17: =AR17/AO17 -> 1 | AU17: Mobile SMS Menu (iOS) | AV17: 898 | AW17: 772 | AX17: 772 | AY17: =AX17/AW17 -> 1 | AZ17: 772 | BA17: =AZ17/AW17 -> 1
A18: out | B18: P24016 | C18: ABOAST0245 | D18: TIPlus-Tiplus Export Local | E18: 522 | F18: 133 | G18: 0 | H18: =G18/F18 -> 0 | I18: 0 | J18: =I18/F18 -> 0 | K18: - | L18: Web | M18: https://bankbnitbk.sharepoint.com/:f:/s/TEST212/Ep78Qlmxo0pEht8rdfyamzoBHfhkycCopqAyr9XvvAECMQ?e=aLtBmW | N18: https://gitlab-dc.bni.co.id/coe-duplicate/test-automation/katalon-tiplus-export-local.git | S18: Katalon​ | AM18: Ibank Remittance Fase 3 | AN18: 400 | AO18: 194 | AP18: 194 | AQ18: =AP18/AO18 -> 1 | AR18: 194 | AS18: =AR18/AO18 -> 1 | AU18: Mobile Banking (Android) | AV18: 11180 | AW18: 1709 | AX18: 1709 | AY18: =AX18/AW18 -> 1 | AZ18: 1709 | BA18: =AZ18/AW18 -> 1
B19: P24016 | C19: ABOAST0245 | D19: TIPlus-Tiplus GB Local | E19: 5264 | F19: 5264 | G19: 812 | H19: =G19/F19 -> 0.15425532 | I19: 812 | J19: =I19/F19 -> 0.15425532 | K19: Nov-Mar | L19: Web | M19: https://bankbnitbk.sharepoint.com/:f:/s/TEST212/EnPhbOuIHQVBn-o711gDTwIB3eOLJ6GgqxeHav5V_212Aw?e=NPMo37 | N19: https://gitlab-dc.bni.co.id/coe-duplicate/test-automation/katalon-tiplus-gb.git | Q19: Andin, Ali, Alkha | R19: Thomas | S19: Katalon​ | AM19: Mobile SMS Menu (Android) | AN19: 898 | AO19: 780 | AP19: 772 | AQ19: =AP19/AO19 -> 0.98974359 | AR19: 772 | AS19: =AR19/AO19 -> 0.98974359 | AU19: Mobile Banking (iOS) | AV19: 11180 | AW19: 1328 | AX19: 1328 | AY19: =AX19/AW19 -> 1 | AZ19: 1328 | BA19: =AZ19/AW19 -> 1
B20: P23108 | C20: AFOAFO0134 | D20: iBank Remitt-Ibank Remittance Fase 1 | E20: 203 | F20: 185 | G20: 185 | H20: =G20/F20 -> 1 | I20: 185 | J20: =I20/F20 -> 1 | K20: Jan-Mar | L20: Web | M20: https://bankbnitbk.sharepoint.com/:f:/s/TEST212/EtmuKzkVd5RIl1KkUpVF9R4BoiHpVsBFUBQoOYHvh7oDPQ?e=kC7VLy | N20: https://gitlab-dc.bni.co.id/coe-duplicate/test-automation/katalon-ibank-remit.git | Q20: Akbar | R20: Thomas | S20: Katalon​ | AM20: Mobile SMS Menu (iOS) | AN20: 898 | AO20: 780 | AP20: 407 | AQ20: =AP20/AO20 -> 0.52179487 | AR20: 407 | AS20: =AR20/AO20 -> 0.52179487 | AU20: Web Agen46 | AV20: 353 | AW20: 329 | AX20: 329 | AY20: =AX20/AW20 -> 1 | AZ20: 329 | BA20: =AZ20/AW20 -> 1 | BD20: Web Agen46 | BE20: Ibank Remittance Fase 1,2 dan 3
B21: P23108 | C21: AFOAFO0134 | D21: iBank Remitt-Ibank Remittance Fase 2 | E21: 481 | F21: 457 | G21: 457 | H21: =G21/F21 -> 1 | I21: 457 | J21: =I21/F21 -> 1 | K21: Mar-Jun | L21: Web | M21: https://bankbnitbk.sharepoint.com/:f:/s/TEST212/ErrL0pVIbCJLm0b1orcWaU8BvqVAwz9-D1w3xohN5Jupmw?e=OSAFJR | N21: https://gitlab-dc.bni.co.id/coe-duplicate/test-automation/katalon-ibank-remit-fase-2.git | Q21: Akbar | R21: Thomas | S21: Katalon​ | AM21: Mobile Banking (Android) | AN21: 11180 | AO21: 1709 | AP21: 1709 | AQ21: =AP21/AO21 -> 1 | AR21: 1709 | AS21: =AR21/AO21 -> 1 | AU21: Mobile Agen46 (Android) | AV21: 712 | AW21: 609 | AX21: 609 | AY21: =AX21/AW21 -> 1 | AZ21: 609 | BA21: =AZ21/AW21 -> 1 | BD21: Mobile Banking | BE21: LMS Wholesale Sprint 1,2,3 dan 4
B22: P23108 | C22: AFOAFO0134 | D22: iBank Remitt-Ibank Remittance Fase 3 | E22: 400 | F22: 194 | G22: 194 | H22: =G22/F22 -> 1 | I22: 194 | J22: =I22/F22 -> 1 | K22: Jun-Oct | L22: Web | M22: https://bankbnitbk.sharepoint.com/:f:/s/TEST212/EkHjWT_UNQVOuyzvn_wuAsIBDRxid-37YpANPr_MFDJmDA?e=sloXmk | N22: https://gitlab-dc.bni.co.id/coe-duplicate/test-automation/katalon-ibank-fase-3.git | Q22: Akbar | R22: Thomas | S22: Katalon​ | AM22: Mobile Banking (iOS) | AN22: 11180 | AO22: 1328 | AP22: 1328 | AQ22: =AP22/AO22 -> 1 | AR22: 1328 | AS22: =AR22/AO22 -> 1 | AU22: Mobile Agen46 (iOS) | AV22: 712 | AW22: 306 | AX22: 306 | AY22: =AX22/AW22 -> 1 | AZ22: 306 | BA22: =AZ22/AW22 -> 1 | BD22: Mobile SMS Menu | BE22: Mobile Wondr Bussiness
B23: P24111 | C23: AFONFO0265 | D23: Wondr-Mobile Wondr Business (Android) | E23: 732 | F23: 80 | G23: 80 | H23: =G23/F23 -> 1 | I23: 80 | J23: =I23/F23 -> 1 | K23: Sep-Nov | L23: Mobile | M23: https://drive.google.com/drive/folders/17ELgFdGoXCIye04cj8w9d-hsfML1s-vV | N23: https://gitlab-dc.bni.co.id/coe-duplicate/test-automation/katalon-wondr-bussiness-android.git | O23: https://bankbnitbk.sharepoint.com/:x:/r/sites/TEST212/Shared%20Documents/General/Sheet%20Monitoring%20Project/UFT%20Katalon%20Automation%202024%20-%202025.xlsx?d=wc03feacd37994a94b2715e297ba9a69e&csf=1&web=1&e=aoQZQg | Q23: Mafa | R23: Mbincar | S23: Katalon​ | AM23: Web Agen46 | AN23: 353 | AO23: 329 | AP23: 329 | AQ23: =AP23/AO23 -> 1 | AR23: 329 | AS23: =AR23/AO23 -> 1 | AU23: Web Portal Admin | AV23: 39 | AW23: 37 | AX23: 37 | AY23: =AX23/AW23 -> 1 | AZ23: 36 | BA23: =AZ23/AX23 -> 0.97297297 | BD23: Mobile Agen46 | BE23: Web Portal Admin
B24: P24111 | C24: AFONFO0265 | D24: Wondr-Mobile Wondr Business (iOS) | E24: 732 | F24: 92 | G24: 92 | H24: =G24/F24 -> 1 | I24: 74 | J24: =I24/F24 -> 0.80434783 | K24: Sep-Nov | L24: Mobile | M24: https://drive.google.com/drive/folders/17ELgFdGoXCIye04cj8w9d-hsfML1s-vV | N24: https://gitlab-dc.bni.co.id/coe-duplicate/test-automation/katalon-wondr-bussiness-ios.git | O24: https://bankbnitbk.sharepoint.com/:x:/r/sites/TEST212/Shared%20Documents/General/Sheet%20Monitoring%20Project/UFT%20Katalon%20Automation%202024%20-%202025.xlsx?d=wc03feacd37994a94b2715e297ba9a69e&csf=1&web=1&e=aoQZQg | Q24: Alvin | R24: Mbincar | S24: Katalon​ | AM24: Mobile Agen46 (Android) | AN24: 712 | AO24: 609 | AP24: 609 | AQ24: =AP24/AO24 -> 1 | AR24: 609 | AS24: =AR24/AO24 -> 1 | AU24: LMS Sprint 1 | AV24: 15 | AW24: 15 | AX24: 15 | AY24: =AX24/AW24 -> 1 | AZ24: 15 | BA24: =AZ24/AW24 -> 1 | BD24: Tiplus SFE | BE24: Digisales Portal
B25: A24001 | C25: AFONFO0229 | D25: SMS Banking-Mobile SMS Menu (Android) | E25: 898 | F25: 780 | G25: 772 | H25: =G25/F25 -> 0.98974359 | I25: 772 | J25: =I25/F25 -> 0.98974359 | K25: Oct-Nov | L25: Mobile | M25: https://bankbnitbk.sharepoint.com/:f:/s/TEST212/EkBwukLUexlCvNbiS9xVLOwBec_4sO1J5vspDybADFMf8g?e=YPNGbQ | N25: https://gitlab-dc.bni.co.id/coe-duplicate/test-automation/katalon-sms-menu-android.git | Q25: Alvin | R25: Mbincar | S25: Katalon​ | AM25: Mobile Agen46 (iOS) | AN25: 712 | AO25: 306 | AP25: 306 | AQ25: =AP25/AO25 -> 1 | AR25: 306 | AS25: =AR25/AO25 -> 1 | AU25: LMS Sprint 2 | AV25: 16 | AW25: 16 | AX25: 16 | AY25: =AX25/AW25 -> 1 | AZ25: 16 | BA25: =AZ25/AW25 -> 1 | BD25: Tiplus UFE | BE25: Digisales APK Generalis dan FTE
B26: A24001 | C26: AFONFO0229 | D26: SMS Banking-Mobile SMS Menu (iOS) | E26: 898 | F26: 780 | G26: 772 | H26: =G26/F26 -> 0.98974359 | I26: 772 | J26: =I26/F26 -> 0.98974359 | K26: Oct-Nov | L26: Mobile | M26: https://bankbnitbk.sharepoint.com/:f:/s/TEST212/EsU0M1xMRx9PokMQJ0xEYqoBFapR-d2DAIfXACNcm1GImQ?e=Td26y3 | N26: https://gitlab-dc.bni.co.id/coe-duplicate/test-automation/katalon-sms-menu-ios.git | Q26: Alvin | R26: Mbincar | S26: Katalon​ | W26: Stop / Aplikasi sudah tidak dilanjutkan scripting / Service Down | AM26: Mobile Credit Card (Android) | AN26: 75 | AO26: 60 | AP26: 40 | AQ26: =AP26/AO26 -> 0.66666667 | AR26: 40 | AS26: =AR26/AO26 -> 0.66666667 | AU26: LMS Sprint 3 | AV26: 37 | AW26: 37 | AX26: 37 | AY26: =AX26/AW26 -> 1 | AZ26: 37 | BA26: =AZ26/AX26 -> 1 | BD26: BNI Direct Lite | BE26: Digisales Browser Generalis dan FTE
B27: A24001 | C27: AFONFO0167 | D27: Mobile Banking (Android) | E27: 11180 | F27: 5590 | G27: 5590 | H27: =G27/F27 -> 1 | I27: 5590 | J27: =I27/F27 -> 1 | K27: Jan-Dec | L27: Mobile | M27: https://bankbnitbk.sharepoint.com/:f:/s/COETeam/EhexkvrncmhPkKrQ88RFFeQBpANxgmBvAXlLKTC6aoqqPw?e=CAjb0u | N27: https://gitlab-dc.bni.co.id/marchy.tio/mobile-banking-android.git | Q27: Adit, Thomas | R27: Thomas | S27: UFT dan Katalon​ | W27: Done | AM27: Mobile Credit Card (iOS) | AN27: 75 | AO27: 60 | AP27: 40 | AQ27: =AP27/AO27 -> 0.66666667 | AR27: 40 | AS27: =AR27/AO27 -> 0.66666667 | AU27: LMS Sprint 4 | AV27: 21 | AW27: 21 | AX27: 21 | AY27: =AX27/AW27 -> 1 | AZ27: 21 | BA27: =AZ27/AX27 -> 1 | BD27: BNI Direct Reguler | BE27: ICONS Tokyo
B28: A24001 | C28: AFONFO0167 | D28: Mobile Banking (iOS) | E28: 11180 | F28: 5590 | G28: 5590 | H28: =G28/F28 -> 1 | I28: 5590 | J28: =I28/F28 -> 1 | K28: Jan-Dec | L28: Mobile | M28: https://bankbnitbk.sharepoint.com/:f:/s/COETeam/EhexkvrncmhPkKrQ88RFFeQBpANxgmBvAXlLKTC6aoqqPw?e=CAjb0u | N28: https://gitlab-dc.bni.co.id/marchy.tio/mobile-agen-ios.git | Q28: Adit, Thomas | R28: Thomas | S28: UFT dan Katalon​ | W28: In Progress | AM28: DMS Sprint 1 | AN28: 134 | AO28: 97 | AP28: 97 | AQ28: =AP28/AO28 -> 1 | AR28: 97 | AS28: =AR28/AO28 -> 1 | AU28: Digisales Portal | AV28: 60 | AW28: 47 | AX28: 47 | AY28: =AX28/AW28 -> 1 | AZ28: 47 | BA28: =AZ28/AW28 -> 1 | BD28: CXO Onboarding | BE28: ICONS Alternity
B29: P23014 | C29: AFOAFO0154 | D29: Keagenan-Web Agen46 | E29: 353 | F29: 329 | G29: 329 | H29: =G29/F29 -> 1 | I29: 329 | J29: =I29/F29 -> 1 | K29: Jan-Dec | L29: Web | M29: https://bankbnitbk.sharepoint.com/:f:/s/TEST212/EgbVkGyr9-pFiln6NEqUKygBcfmEacAgN3FK0RjDiivwMg?e=nPUY5s | N29: https://gitlab-dc.bni.co.id/marchy.tio/keagenan46-uft.git | P29: dev_alex | Q29: Yusuf, Alex | R29: Thomas, Marin | S29: UFT​ | T29: Oppo Reno 7 | W29: Hold | AM29: DMS Sprint 2 | AN29: 136 | AO29: 136 | AP29: 136 | AQ29: =AP29/AO29 -> 1 | AR29: 136 | AS29: =AR29/AO29 -> 1 | AU29: Digisales Generalis Mobile Browser | AV29: 49 | AW29: 47 | AX29: 47 | AY29: =AX29/AW29 -> 1 | AZ29: 47 | BA29: =AZ29/AW29 -> 1 | BD29: DigiMS | BE29: ICONS Poisedon
B30: P23014 | C30: AFOAFO0154 | D30: Keagenan-Mobile Agen46 (Android) | E30: 712 | F30: 609 | G30: 609 | H30: =G30/F30 -> 1 | I30: 609 | J30: =I30/F30 -> 1 | K30: Jan-Dec | L30: Mobile | M30: https://bankbnitbk.sharepoint.com/:f:/s/TEST212/EiEcoPf2gTxAmcZmpvA4fNgBhiFsoebZ1LZC4eefKSbWvg?e=nX1kh8 | N30: https://gitlab-dc.bni.co.id/marchy.tio/mobile-agen-android.git | P30: dev_yudho | Q30: Akbar, Yudho | R30: Thomas, Mbincar, Marin | S30: UFT​ | AM30: DMS Sprint 3 | AN30: 210 | AO30: 210 | AP30: 210 | AQ30: =AP30/AO30 -> 1 | AR30: 210 | AS30: =AR30/AO30 -> 1 | AU30: Digisales Generalis Mobile APK | AV30: 49 | AW30: 47 | AX30: 47 | AY30: =AX30/AW30 -> 1 | AZ30: 47 | BA30: =AZ30/AW30 -> 1 | BD30: Mobile MyCard | BE30: ICONS London
B31: P23014 | C31: AFOAFO0154 | D31: Keagenan-Mobile Agen46 (iOS) | E31: 712 | F31: 609 | G31: 609 | H31: =G31/F31 -> 1 | I31: 609 | J31: =I31/F31 -> 1 | K31: Jan-Dec | L31: Mobile | M31: https://bankbnitbk.sharepoint.com/:f:/s/TEST212/EgPcgA5jbJ9HrcgZ-GhhgCMB0UPYbPOvpQPH74Hk7dO4bA?e=8KbZ6f | N31: https://gitlab-dc.bni.co.id/marchy.tio/mobile-agen-ios.git | Q31: Thomas | R31: Thomas | S31: UFT​ | T31: iPhone SE | AM31: BAMS-TAT | AN31: 423 | AO31: 390 | AP31: 202 | AQ31: =AP31/AO31 -> 0.51794872 | AR31: 202 | AS31: =AR31/AO31 -> 0.51794872 | AU31: Digisales FTE Mobile Browser | AV31: 257 | AW31: 257 | AX31: 257 | AY31: =AX31/AW31 -> 1 | AZ31: 249 | BA31: =AZ31/AW31 -> 0.9688716 | BD31: DMS Sprint 1,2 dan 3
B32: A24001 | C32: AFONFO0173 | D32: MyCard-Mobile Credit Card (Android) | E32: 75 | F32: 60 | G32: 40 | H32: =G32/F32 -> 0.66666667 | I32: 40 | J32: =I32/F32 -> 0.66666667 | K32: Oct-Oct | L32: Mobile | M32: https://bankbnitbk.sharepoint.com/:f:/s/TEST212/EhxlVjo9HBdAm-H7eawQ7tABiE5bT5QZOeaXojeQgwtHig?e=cce0WK | N32: https://gitlab-dc.bni.co.id/marchy.tio/mobile-bni-credit-card-android.git | Q32: Willy | R32: Thomas | S32: Katalon​ | W32: normal | AM32: DigIMS | AN32: 198 | AO32: 115 | AP32: 115 | AQ32: =AP32/AO32 -> 1 | AR32: 115 | AS32: =AR32/AO32 -> 1 | AU32: Digisales FTE Mobile APK | AV32: 257 | AW32: 257 | AX32: 257 | AY32: =AX32/AW32 -> 1 | AZ32: 254 | BA32: =AZ32/AW32 -> 0.98832685
B33: A24001 | C33: AFONFO0173 | D33: MyCard-Mobile Credit Card (iOS) | E33: 75 | F33: 60 | G33: 40 | H33: =G33/F33 -> 0.66666667 | I33: 40 | J33: =I33/F33 -> 0.66666667 | K33: Oct-Oct | L33: Mobile | M33: https://bankbnitbk.sharepoint.com/:f:/s/TEST212/Ei5Zf9cttb5EjDeqTlOL06QBpKaucm6Sp8TatRFM_m3syg?e=Co7C5G | N33: https://gitlab-dc.bni.co.id/marchy.tio/mobile-bni-credit-card-ios.git | Q33: Thomas | R33: Thomas | S33: Katalon​ | V33: 7 hari | W33: 20 tc | X33: 25 hari | AM33: Digisales Portal | AN33: 60 | AO33: 47 | AP33: 47 | AQ33: =AP33/AO33 -> 1 | AR33: 47 | AS33: =AR33/AO33 -> 1 | AU33: Smart VA Portal | AV33: 669 | AW33: 669 | AX33: 157 | AY33: =AX33/AW33 -> 0.23467862 | AZ33: 157 | BA33: =AZ33/AW33 -> 0.23467862
B34: P23095 | C34: AMOOES0255 | D34: Document Management System-Sprint 1 | E34: 134 | F34: 97 | G34: 97 | H34: =G34/F34 -> 1 | I34: 97 | J34: =I34/F34 -> 1 | K34: Oct-Oct | L34: Web | M34: https://bankbnitbk.sharepoint.com/:f:/s/TEST212/EmHMOIlBNDhMgG0fqwfNLcMByJKReKkvJNI9KYFvfC6wag?e=8drVel | N34: https://gitlab-dc.bni.co.id/coe-duplicate/test-automation/katalon-dms.git | Q34: Willy | R34: Thomas | S34: Katalon​ | V34: 7 hari | W34: 20 tc | AM34: Digisales Generalis Mobile Browser | AN34: 49 | AO34: 47 | AP34: 47 | AQ34: =AP34/AO34 -> 1 | AR34: 47 | AS34: =AR34/AO34 -> 1
B35: P23095 | C35: AMOOES0255 | D35: Document Management System-Sprint 2 | E35: 136 | F35: 136 | G35: 136 | H35: =G35/F35 -> 1 | I35: 136 | J35: =I35/F35 -> 1 | K35: Oct-Nov | L35: Web | M35: https://bankbnitbk.sharepoint.com/:f:/s/TEST212/EpY4prIHBUtLrQN9JOy0ISEBtNP6CEy567sXf4qNOFEo7Q?e=bRxJ5j | N35: https://gitlab-dc.bni.co.id/coe-duplicate/test-automation/katalon-dms.git | Q35: Willy | R35: Thomas | S35: Katalon​ | V35: 11 hari | W35: 20 tc | AM35: Digisales Generalis Mobile APK | AN35: 49 | AO35: 47 | AP35: 47 | AQ35: =AP35/AO35 -> 1 | AR35: 47 | AS35: =AR35/AO35 -> 1
B36: P23095 | C36: AMOOES0255 | D36: Document Management System-Sprint 3 | E36: 210 | F36: 210 | G36: 210 | H36: =G36/F36 -> 1 | I36: 210 | J36: =I36/F36 -> 1 | K36: Nov-Dec | L36: Web | M36: https://bankbnitbk.sharepoint.com/:f:/s/TEST212/Erxs-oPMn19Air8-liocoq4BGeFyQJ0enNcHClbhAI4e2Q?e=zUdiKh | N36: https://gitlab-dc.bni.co.id/coe-duplicate/test-automation/katalon-dms.git | Q36: Willy | R36: Thomas | S36: Katalon​ | V36: 22 hari / 1 bulan | W36: 20 tc | AM36: Digisales FTE Mobile Browser | AN36: 257 | AO36: 257 | AP36: 257 | AQ36: =AP36/AO36 -> 1 | AR36: 249 | AS36: =AR36/AO36 -> 0.9688716
B37: P23144 | C37: AMOLOM0174 | D37: New BAMS & CPR-BAMS-TAT | E37: 423 | F37: 390 | G37: 362 | H37: =G37/F37 -> 0.92820513 | I37: 362 | J37: =I37/F37 -> 0.92820513 | K37: Oct-Jan | L37: Web | M37: https://bankbnitbk.sharepoint.com/:f:/s/TEST212/EmiB9mpkX1tFldLUVOVY5SsBY1WjAqn_mc_ygxcWlPhRfg?e=442imQ | N37: https://gitlab-dc.bni.co.id/coe-duplicate/test-automation/katalon-bams-tat.git | Q37: Burhan | R37: Thomas | S37: Katalon​ | V37: 10 hari | W37: 20 tc | AM37: Digisales FTE Mobile APK | AN37: 257 | AO37: 257 | AP37: 257 | AQ37: =AP37/AO37 -> 1 | AR37: 254 | AS37: =AR37/AO37 -> 0.98832685
B38: P23094 | C38: AMOOES0309 | D38: DigIMS | E38: 1153 | F38: 1137 | G38: 590 | H38: =G38/F38 -> 0.51890941 | I38: 583 | J38: =I38/F38 -> 0.51275286 | K38: Oct-Nov | L38: Web | M38: https://bankbnitbk.sharepoint.com/:f:/s/TEST212/EmDQeI6wuE9Erk-8RtI6KBsBdR4mp5abwD8GJYpgrlXEyA?e=FOsV8R | N38: https://gitlab-dc.bni.co.id/coe-duplicate/test-automation/katalon-digims.git | Q38: Alkha | R38: Thomas | S38: Katalon​ | V38: 3 hari | W38: 20 tc | X38: 35 hari/ 1 bulan 2 minggu | AM38: Smart VA Portal | AN38: 669 | AO38: 669 | AP38: 157 | AQ38: =AP38/AO38 -> 0.23467862 | AR38: 157 | AS38: =AR38/AO38 -> 0.23467862
B39: P24091 | C39: AMOSAL0068 | D39: Digisales-Portal (4B) | E39: 60 | F39: 47 | G39: 47 | H39: =G39/F39 -> 1 | I39: 47 | J39: =I39/F39 -> 1 | K39: Oct-Nov | L39: Web | M39: https://bankbnitbk.sharepoint.com/:f:/s/TEST212/EpwQ_mowTgRIsBNX-yqk1SsBydKz148dpodB8gftHbFBaw?e=24HPLd | N39: https://gitlab-dc.bni.co.id/coe-duplicate/test-automation/katalon-digisales-portal.git | S39: Katalon​ | V39: 3 hari | W39: 20 tc | AM39: Cash Management Lite | AN39: 29603 | AO39: 29603 | AP39: 28 | AQ39: =AP39/AO39 -> 0.00094585008 | AR39: 18 | AS39: =AR39/AO39 -> 0.00060804648
B40: P24091 | C40: AMOSAL0068 | D40: Digisales-Generalis Mobile Browser (4B) | E40: 49 | F40: 47 | G40: 47 | H40: =G40/F40 -> 1 | I40: 47 | J40: =I40/F40 -> 1 | K40: Oct-Nov | L40: Mobile | M40: https://bankbnitbk.sharepoint.com/:f:/s/TEST212/ElybKHNWvkxDjZztpmaLLWUBbK7bk4AXKBTpXRbjFe-LvQ?e=zw4Rt1 | N40: https://gitlab-dc.bni.co.id/coe-duplicate/test-automation/katalon-digisales-generalis-mobile-browser.git | S40: Katalon​ | V40: 3 hari | W40: 20 tc | AM40: GB Online | AN40: 555 | AO40: 420 | AP40: 0 | AQ40: =AP40/AO40 -> 0 | AR40: 0 | AS40: =AR40/AO40 -> 0
B41: P24091 | C41: AMOSAL0068 | D41: Digisales-Generalis Mobile APK (4B) | E41: 49 | F41: 47 | G41: 47 | H41: =G41/F41 -> 1 | I41: 47 | J41: =I41/F41 -> 1 | K41: Oct-Nov | L41: Mobile | M41: https://bankbnitbk.sharepoint.com/:f:/s/TEST212/ElM4wgKu4IpEo1aN26W6_xEBbG1DgM8lJCMGlpG4MzZ0Mg?e=ugHmtA | N41: https://gitlab-dc.bni.co.id/coe-duplicate/test-automation/katalon-digisales-generalis-mobile-apk.git | Q41: Unedo | S41: Katalon​ | V41: 13 hari | W41: 20 tc
B42: P24091 | C42: AMOSAL0068 | D42: Digisales-FTE Mobile Browser (4B) | E42: 257 | F42: 257 | G42: 257 | H42: =G42/F42 -> 1 | I42: 249 | J42: =I42/F42 -> 0.9688716 | K42: Nov-Dec | L42: Mobile | M42: https://bankbnitbk.sharepoint.com/:f:/s/TEST212/Eup95DJS-rFLljrtCvblvq0BOzTzM9ulTTYDds9KCmcULw?e=eHpNAF | N42: https://gitlab-dc.bni.co.id/coe-duplicate/test-automation/katalon-digisales-fte-mobile-browser.git | S42: Katalon​ | V42: 13 hari | W42: 20 tc
...

Sheet Monthly Monitoring (2026)
B1: ="Last Update "&TEXT(NOW(),"DD MMMM YYYY HH:MM")&" WIB" -> Last Update 28 July 2026 16:18 WIB
B3: Data Capaian
B4: No | C4: Npp | D4: Nama | E4: Aplikasi | F4: Januari | G4: Februari | H4: Maret | I4: April | J4: Mei | K4: Juni | L4: Juli | M4: Agustus | N4: September | O4: Oktober | P4: November | Q4: Desember
B5: 1 | C5: P057974 | D5: SIlvester Kevin
B6: 2 | C6: P063945 | D6: Thomas Gunawan Sardjono
B7: 3 | C7: P062927 | D7: Marinda Ika Dewi Sakariana
B8: 4 | C8: P062928 | D8: Mbincar Rukun Sembiring
B9: 5 | C9: 821905 | D9: Burhan Aditya
B10: 6 | C10: 900654 | D10: Syafiq Ali Zhafran
B11: 7 | C11: 900800 | D11: Willy Honandar
B12: 8 | C12: 901164 | D12: Alfiko Utama
B13: 9 | C13: 901232 | D13: Mikhael Adriel Pratama Gana
B14: 10 | C14: 901233 | D14: Izaaz Waskito Widyarto
B15: 11 | C15: 901244 | D15: Dani Yudistira Maulana
B16: 12 | C16: 901450 | D16: Hanif Razin Rahmatullah
B17: 13 | C17: 901742 | D17: Pierre Azhanzi Ibrahim (Autodebet)
B18: 14 | C18: 901779 | D18: Zakiah Putri Madani (Avatar)
B19: 15 | C19: 901780 | D19: Marcelino Oktaviansyah (Avatar)
B20: 16 | C20: 901856 | D20: Firizki Fajri
... B23: 19 | C23: 901895 | D23: Abdul Aziz Permana (Avatar)

Sheet Weekly TC Application (2024)
B1: Last Update 04 October 2024 08:10 WIB
B3: Data Capaian Scripting per-Individu
B4: No | C4: Npp | D4: Nama | E4: Aplikasi | F4: 2024 | G4: Jan-W1 | H4: Jan-W2 | I4: Jan-W3 | J4: Jan-W4 | K4: Jan-W5 | L4: Feb-W1 | M4: Feb-W2 | N4: Feb-W3 | O4: Feb-W4 | P4: Mar-W1 | Q4: Mar-W2 | R4: Mar-W3 | S4: Mar-W4 | T4: Apr-W1 | U4: Apr-W2 | V4: Apr-W3 | W4: Apr-W4 | X4: May-W1 | Y4: May-W2 | Z4: May-W3 | AA4: May-W4 | AB4: May-W5 | AC4: Jun-W1 | AD4: Jun-W2 | AE4: Jun-W3 | AF4: Jun-W4 | AG4: Jul-W1 | AH4: Jul-W2 | AI4: Jul-W3 | AJ4: Jul-W4 | AK4: Jul-W5 | AL4: Aug-W1 | AM4: Aug-W2 | AN4: Aug-W3 | AO4: Aug-W4 | AP4: Sep-W1 | AQ4: Sep-W2 | AR4: Sep-W3 | AS4: Sep-W4 | AT4: Oct-W1 | AU4: Oct-W2 | AV4: Oct-W3 | AW4: Oct-W4 | AX4: Oct-W5 | AY4: Nov-W1 | AZ4: Nov-W2 | BA4: Nov-W3 | BB4: Nov-W4 | BC4: Dec-W1 | BD4: Dec-W2 | BE4: Dec-W3 | BF4: Dec-W4
B5: 1 | C5: P057974 | D5: SIlvester Kevin | E5: - | F5: =SUM(F6:F23) -> 3251 | G5: - | H5: - | I5: - | J5: - | K5: - | L5: - | M5: - | N5: - | O5: - | P5: - | Q5: - | R5: - | S5: - | T5: - | U5: - | V5: - | W5: - | X5: - | Y5: - | Z5: - | AA5: - | AB5: - | AC5: - | AD5: - | AE5: - | AF5: - | AG5: - | AH5: - | AI5: - | AJ5: - | AK5: - | AL5: - | AM5: - | AN5: - | AO5: - | AP5: - | AQ5: - | AR5: - | AS5: - | AT5: - | AU5: - | AV5: - | AW5: - | AX5: - | AY5: - | AZ5: - | BA5: - | BB5: - | BC5: - | BD5: - | BE5: - | BF5: -
B6: 2 | C6: P063945 | D6: Thomas Gunawan Sardjono | E6: BNI Direct Lite | F6: =SUM(G6:BF6) -> 922 | G6: 0 | H6: 0 | I6: 0 | J6: 0 | K6: 0 | L6: 0 | M6: 0 | N6: 0 | O6: 0 | P6: 0 | Q6: 416 | R6: 0 | S6: 0 | T6: 0 | U6: 0 | V6: 0 | W6: 0 | X6: 0 | Y6: 415 | Z6: 7 | AA6: 7 | AB6: 11 | AC6: 20 | AD6: 6 | AE6: 9 | AF6: 0 | AG6: 9 | AH6: 3 | AI6: 2 | AJ6: 7 | AK6: 7 | AL6: 3 | AM6: 0 | AN6: 0 | AO6: 0 | AP6: 0 | AQ6: 0 | AR6: 0 | AS6: 0 | AT6: 0 | AU6: 0 | AV6: 0 | AW6: 0 | AX6: 0 | AY6: 0 | AZ6: 0 | BA6: 0 | BB6: 0 | BC6: 0 | BD6: 0 | BE6: 0 | BF6: 0
E7: CXO Onboarding | F7: =SUM(G7:BF7) -> 0 | G7: 0 | H7: 0 | I7: 0 | J7: 0 | K7: 0 | L7: 0 | M7: 0 | N7: 0 | O7: 0 | P7: 0 | Q7: 0 | R7: 0 | S7: 0 | T7: 0 | U7: 0 | V7: 0 | W7: 0 | X7: 0 | Y7: 0 | Z7: 0 | AA7: 0 | AB7: 0 | AC7: 0 | AD7: 0 | AE7: 0 | AF7: 0 | AG7: 0 | AH7: 0 | AI7: 0 | AJ7: 0 | AK7: 0 | AL7: 0 | AM7: 0 | AN7: 0 | AO7: 0 | AP7: 0 | AQ7: 0 | AR7: 0 | AS7: 0 | AT7: 0 | AU7: 0 | AV7: 0 | AW7: 0 | AX7: 0 | AY7: 0 | AZ7: 0 | BA7: 0 | BB7: 0 | BC7: 0 | BD7: 0 | BE7: 0 | BF7: 0
E8: Tiplus SFE | F8: =SUM(G8:BF8) -> 218 | G8: 0 | H8: 0 | I8: 0 | J8: 0 | K8: 0 | L8: 0 | M8: 0 | N8: 0 | O8: 0 | P8: 0 | Q8: 0 | R8: 0 | S8: 0 | T8: 0 | U8: 0 | V8: 0 | W8: 0 | X8: 0 | Y8: 0 | Z8: 0 | AA8: 0 | AB8: 0 | AC8: 0 | AD8: 3 | AE8: 7 | AF8: 2 | AG8: 9 | AH8: 37 | AI8: 34 | AJ8: 30 | AK8: 35 | AL8: 28 | AM8: 9 | AN8: 12 | AO8: 12 | AP8: 0 | AQ8: 0 | AR8: 0 | AS8: 0 | AT8: 0 | AU8: 0 | AV8: 0 | AW8: 0 | AX8: 0 | AY8: 0 | AZ8: 0 | BA8: 0 | BB8: 0 | BC8: 0 | BD8: 0 | BE8: 0 | BF8: 0
E9: Tiplus UFE | F9: =SUM(G9:BF9) -> 0
E10: Web Agen46 | F10: =SUM(G10:BF10) -> 1003 | G10: 1000 | H10: 0 | I10: 1 | J10: 2
B11: 3 | C11: P062927 | D11: Marinda Ika Dewi Sakariana | E11: ICONS Tokyo | F11: =SUM(G11:BF11) -> 171 | G11: 171 | H11: 0 | I11: 0 | J11: 0 | K11: 0 | L11: 0 | M11: 0 | N11: 0 | O11: 0 | P11: 0 | Q11: 0 | R11: 0 | S11: 0 | T11: 0 | U11: 0 | V11: 0 | W11: 0 | X11: 0 | Y11: 0 | Z11: 0 | AA11: 0 | AB11: 0 | AC11: 0 | AD11: 0
E12: ICONS London | F12: =SUM(G12:BF12) -> 650 | G12: 0 | H12: 0 | I12: 0 | J12: 0 | K12: 0 | L12: 0 | M12: 0 | N12: 0 | O12: 0 | P12: 0 | Q12: 0 | R12: 0 | S12: 0 | T12: 0 | U12: 0 | V12: 0 | W12: 650 | X12: 0 | Y12: 0 | Z12: 0 | AA12: 0 | AB12: 0 | AC12: 0 | AD12: 0
E13: ICONS Alternity | F13: =SUM(G13:BF13) -> 0
E14: ICONS Poseidon | F14: =SUM(G14:BF14) -> 120 | G14: 0 | H14: 15 | I14: 15 | J14: 0 | K14: 0 | L14: 2 | M14: 25 | N14: 1 | O14: 0 | P14: 10 | Q14: 11 | R14: 22 | S14: 10 | T14: 0 | U14: 0 | V14: 0 | W14: 0 | X14: 0 | Y14: 0 | Z14: 8 | AA14: 1 | AB14: 0 | AC14: 0 | AD14: 0
B15: 4 | C15: P062928 | D15: Mbincar Rukun Sembiring | E15: Ibank Remittance Fase 1 | F15: =SUM(G15:BF15) -> 0
E16: Ibank Remittance Fase 2 | F16: =SUM(G16:BF16) -> 0
E17: Ibank Remittance Fase 3 | F17: =SUM(G17:BF17) -> 0
E18: BNI Direct Reguler / Reskining | F18: =SUM(G18:BF18) -> 0
E19: SMS Menu (Android) | F19: =SUM(G19:BF19) -> 0
E20: Wondr Bussiness | F20: =SUM(G20:BF20) -> 0
E21: LMS Wholesale Sprint 1 | F21: =SUM(G21:BF21) -> 0
E22: CXO Onboarding | F22: =SUM(G22:BF22) -> 0
E23: Web Agen46 | F23: =SUM(G23:BF23) -> 167 | G23: 0 | H23: 0 | I23: 0 | J23: 0 | K23: 0 | L23: 0 | M23: 65 | N23: 102 | O23: 0 | P23: 0 | Q23: 0 | R23: 0 | S23: 0 | T23: 0 | U23: 0 | V23: 0 | W23: 0 | X23: 0 | Y23: 0 | Z23: 0 | AA23: 0 | AB23: 0 | AC23: 0 | AD23: 0
B24: 5 | C24: 821905 | D24: Burhan Aditya | E24: BNI Direct Lite | F24: =SUM(G24:BF24) -> 7 | G24: 0 | H24: 0 | I24: 0 | J24: 0 | K24: 0 | L24: 0 | M24: 0 | N24: 0 | O24: 0 | P24: 0 | Q24: 0 | R24: 0 | S24: 0 | T24: 0 | U24: 0 | V24: 0 | W24: 1 | X24: 6 | Y24: 0 | Z24: 0 | AA24: 0 | AB24: 0 | AC24: 0 | AD24: 0
E25: Mobile Banking (Android) | F25: =SUM(G25:BF25) -> 0
E26: BAMS-TAT
B27: 6 | C27: 900674 | D27: Andinira Rizki Syafitri | E27: Tiplus SFE | F27: =SUM(G27:BF27) -> 0
E28: Tiplus Export Local | F28: =SUM(G28:BF28) -> 87 | G28: 0 | H28: 0 | I28: 0 | J28: 0 | K28: 0 | L28: 0 | M28: 0 | N28: 0 | O28: 0 | P28: 0 | Q28: 0 | R28: 0 | S28: 0 | T28: 0 | U28: 0 | V28: 0 | W28: 0 | Z28: 6 | AA28: 5 | AB28: 12 | AC28: 19 | AD28: 6 | AE28: 2 | AF28: 7 | AG28: 9 | AH28: 2 | AI28: 2 | AJ28: 10 | AK28: 7
B29: 7 | C29: 900733 | D29: Al Khawarismi Atma Pratama | E29: Tiplus UFE | F29: =SUM(G29:BF29) -> 171 | G29: 171 | H29: 0 | I29: 0 | J29: 0 | K29: 0 | L29: 0 | M29: 0 | N29: 0 | O29: 0 | P29: 0 | Q29: 0 | R29: 0 | S29: 0 | T29: 0 | U29: 0 | V29: 0 | W29: 0 | X29: 0 | Y29: 0 | Z29: 0 | AA29: 0 | AB29: 0 | AC29: 0 | AD29: 0
E30: Web Agen46 | F30: =SUM(G30:BF30) -> 415 | G30: 0 | H30: 0 | I30: 0 | J30: 0 | K30: 0 | L30: 0 | M30: 0 | N30: 0 | O30: 0 | P30: 0 | Q30: 415 | R30: 0 | S30: 0 | T30: 0 | U30: 0 | V30: 0 | W30: 0 | X30: 0 | Y30: 0 | Z30: 0 | AA30: 0 | AB30: 0 | AC30: 0 | AD30: 0
E31: DigIMS
B32: 8 | C32: 900692 | D32: Muhamad Ilyas Azmi Dewanto | E32: CXO Onboarding | F32: =SUM(G32:BF32) -> 366 | G32: 0 | H32: 0 | I32: 0 | J32: 0 | K32: 0 | L32: 0 | M32: 0 | N32: 4 | O32: 0 | P32: 0 | Q32: 0 | R32: 10 | S32: 0 | T32: 18 | U32: 37 | V32: 4 | W32: 3 | X32: 16 | Y32: 27 | Z32: 24 | AA32: 41 | AB32: 26 | AC32: 43 | AD32: 0 | AE32: 3 | AF32: 14 | AG32: 8 | AH32: 13 | AI32: 23 | AJ32: 38 | AK32: 14
F33: =SUM(G33:BF33) -> 0
B34: 9 | C34: 900800 | D34: Willy Honandar | E34: Mobile Credit Card (Android) | F34: =SUM(G34:BF34) -> 118 | G34: 0 | H34: 0 | I34: 0 | J34: 0 | K34: 0 | L34: 0 | M34: 0 | N34: 0 | O34: 0 | P34: 0 | Q34: 0 | R34: 0 | S34: 0 | T34: 0 | U34: 0 | V34: 0 | W34: 9 | X34: 1 | Y34: 7 | Z34: 29 | AA34: 22 | AB34: 21 | AC34: 0 | AD34: 0 | AH34: 17 | AI34: 4 | AJ34: 4 | AL34: 4
E35: Mobile Credit Card (iOS) | F35: =SUM(G35:BF35) -> 0 | G35: 0 | H35: 0 | I35: 0 | J35: 0 | K35: 0 | L35: 0 | M35: 0 | N35: 0 | O35: 0 | P35: 0 | Q35: 0 | R35: 0 | S35: 0 | T35: 0 | U35: 0 | V35: 0 | W35: 0 | X35: 0 | Y35: 0 | Z35: 0 | AA35: 0 | AB35: 0 | AC35: 0 | AD35: 0
E36: DMS Sprint 1
E37: DMS Sprint 2
E38: DMS Sprint 3
B39: 10 | C39: 900654 | D39: Syafiq Ali Zhafran | E39: Tiplus Guarante Bank | F39: =SUM(G39:BF39) -> 0 | G39: 0 | H39: 0 | I39: 0 | J39: 0 | K39: 0 | L39: 0 | M39: 0 | N39: 0 | O39: 0 | P39: 0 | Q39: 0 | R39: 0 | S39: 0 | T39: 0 | U39: 0 | V39: 0 | W39: 0 | X39: 0 | Y39: 0 | Z39: 0 | AA39: 0 | AB39: 0 | AC39: 0 | AD39: 0
F40: =SUM(G40:BF40) -> 49 | G40: 0 | H40: 0 | I40: 0 | J40: 0 | K40: 0 | L40: 0 | M40: 0 | N40: 0 | O40: 0 | P40: 0 | Q40: 0 | R40: 0 | S40: 0 | T40: 0 | U40: 0 | V40: 0 | W40: 0 | X40: 0 | Y40: 0 | Z40: 0 | AA40: 0 | AB40: 0 | AC40: 0 | AD40: 0 | AE40: 0 | AF40: 0 | AG40: 0 | AH40: 0 | AI40: 0 | AJ40: 39 | AK40: 9 | AL40: 1
B41: 11 | C41: 821972 | D41: Yusuf Tri Wibowo | E41: ICONS Alternity | F41: =SUM(G41:BF41) -> 0 | G41: 0 | H41: 0 | I41: 0 | J41: 0 | K41: 0 | L41: 0 | M41: 0 | N41: 0 | O41: 0 | P41: 0 | Q41: 0 | R41: 0 | S41: 0 | T41: 0 | U41: 0 | V41: 0 | W41: 0 | X41: 0 | Y41: 0 | Z41: 0 | AA41: 0 | AB41: 0 | AC41: 0 | AD41: 0 | AE41: 0 | AF41: 0 | AG41: 0 | AH41: 0 | AI41: 0
...

Sheet Weekly TC Team
C1: Last Update 04 October 2024 08:10 WIB
B4: Year | D4: Thomas Gunawan Sardjono | E4: Andinira Rizki Syafitri | F4: Al Khawarismi Atma Pratama | G4: Burhan Aditya | H4: Muhamad Ilyas Azmi Dewanto | I4: Willy Honandar
C5: 2024 | D5: 0 | E5: 0 | F5: 0 | G5: 0 | H5: 0 | I5: 0
B6: January | C6: Jan-W1 | D6: 25 | E6: 0 | F6: 0 | G6: 0 | H6: 0 | I6: 0
C7: Jan-W2 | D7: 50 | E7: 0 | F7: 0 | G7: 0 | H7: 0 | I7: 0
C8: Jan-W3 | D8: 75 | E8: 0 | F8: 0 | G8: 0 | H8: 0 | I8: 0
C9: Jan-W4 | D9: 25 | E9: 0 | F9: 0 | G9: 0 | H9: 0 | I9: 0
C10: Jan-W5 | D10: 50 | E10: 0 | F10: 0 | G10: 0 | H10: 0 | I10: 0
B12: February | C12: Feb-W1 | D12: 50 | E12: 0 | F12: 0 | G12: 0 | H12: 0 | I12: 0
C13: Feb-W2 | D13: 75 | E13: 0 | F13: 0 | G13: 0 | H13: 0 | I13: 0
C14: Feb-W3 | D14: 25 | E14: 0 | F14: 0 | G14: 0 | H14: 0 | I14: 0
C15: Feb-W4 | D15: 50 | E15: 0 | F15: 0 | G15: 0 | H15: 0 | I15: 0
B17: March | C17: Mar-W1 | D17: 75 | E17: 0 | F17: 0 | G17: 0 | H17: 0 | I17: 0
C18: Mar-W2 | D18: 25 | E18: 0 | F18: 0 | G18: 0 | H18: 0 | I18: 0
C19: Mar-W3 | D19: 50 | E19: 0 | F19: 0 | G19: 0 | H19: 0 | I19: 0
C20: Mar-W4 | D20: 75 | E20: 0 | F20: 0 | G20: 0 | H20: 0 | I20: 0
B22: April | C22: Apr-W1 | D22: 40 | E22: 0 | F22: 0 | G22: 0 | H22: 0 | I22: 0
C23: Apr-W2 | D23: 40 | E23: 0 | F23: 0 | G23: 0 | H23: 0 | I23: 0
C24: Apr-W3 | D24: 40 | E24: 0 | F24: 0 | G24: 0 | H24: 0 | I24: 0
C25: Apr-W4 | D25: 40 | E25: 0 | F25: 0 | G25: 0 | H25: 0 | I25: 0
B27: May | C27: May-W1 | D27: 40 | E27: 0 | F27: 0 | G27: 0 | H27: 0 | I27: 0
C28: May-W2 | D28: 40 | E28: 0 | F28: 0 | G28: 0 | H28: 0 | I28: 0
C29: May-W3 | D29: 40 | E29: 0 | F29: 0 | G29: 0 | H29: 0 | I29: 0
C30: May-W4 | D30: 40 | E30: 0 | F30: 0 | G30: 0 | H30: 0 | I30: 0
C31: May-W5 | D31: 40 | E31: 0 | F31: 0 | G31: 0 | H31: 0 | I31: 0
B33: June | C33: Jun-W1 | D33: 40 | E33: 0 | F33: 0 | G33: 0 | H33: 0 | I33: 0
C34: Jun-W2 | D34: 40 | E34: 0 | F34: 0 | G34: 0 | H34: 0 | I34: 0
C35: Jun-W3 | D35: 40 | E35: 0 | F35: 0 | G35: 0 | H35: 0 | I35: 0
C36: Jun-W4 | D36: 40 | E36: 0 | F36: 0 | G36: 0 | H36: 0 | I36: 0
B38: July | C38: Jul-W1 | D38: 40 | E38: 0 | F38: 0 | G38: 0 | H38: 0 | I38: 0
C39: Jul-W2 | D39: 40 | E39: 0 | F39: 0 | G39: 0 | H39: 0 | I39: 0
C40: Jul-W3 | D40: 40 | E40: 0 | F40: 0 | G40: 0 | H40: 0 | I40: 0
C41: Jul-W4 | D41: 40 | E41: 0 | F41: 0 | G41: 0 | H41: 0 | I41: 0
C42: Jul-W5 | D42: 40 | E42: 0 | F42: 0 | G42: 0 | H42: 0 | I42: 0
B44: August | C44: Aug-W1 | D44: 40 | E44: 0 | F44: 0 | G44: 0 | H44: 0 | I44: 0
C45: Aug-W2 | D45: 40 | E45: 0 | F45: 0 | G45: 0 | H45: 0 | I45: 0
C46: Aug-W3 | D46: 40 | E46: 0 | F46: 0 | G46: 0 | H46: 0 | I46: 0
C47: Aug-W4 | D47: 40 | E47: 0 | F47: 0 | G47: 0 | H47: 0 | I47: 0
B49: September | C49: Sep-W1 | D49: 40 | E49: 0 | F49: 0 | G49: 0 | H49: 0 | I49: 0
C50: Sep-W2 | D50: 40 | E50: 0 | F50: 0 | G50: 0 | H50: 0 | I50: 0
...

Sheet Daftar Aplikasi BNI
A1: DAFTAR APLIKASI AKTIF BNI
A2: STA - ISA
A4: Application ID | B4: Nama Aplikasi | C4: Description/Definition | D4: Main Building Block | E4: Sub Building Block | F4: Business Owner | G4: System Owner | H4: Team APS | I4: Criticality | J4: Status | K4: Transactional/ Mission Critical Product (1) | L4: Regulatory (BI/ OJK/ SWIFT/MC/ VISA/GPN) (2) | M4: Revenue Loss /Biz Critical (1) | N4: Operational Impact (Bank wide (1)) | O4: Reputation/ Customer facing(1) | P4: Criticality Score
A5: AMOLOM0001 | B5: ADK NET - Elektronik Administrasi Kredit | C5: Aplikasi untuk proses administrasi kredit, terdiri dari: eADK Home, ePK, ePolis, eAkta, eTaksasi, eSettlement, eRekanan, eFilling | D5: Operational Services | E5: Loan Operations | F5: COP | G5: RDL - Retail Credit Operation Delivery | H5: BOA | I5: 3-Moderate | J5: Aktif | K5: 0 | L5: 0 | M5: 1 | N5: 1 | O5: 0 | P5: 2
A6: AMORAC0002 | B6: Ambit Focus - IRRBB (Interest Rate Risk In The Banking Book) | C6: Aplikasi utk perhitungan resiko tingkat suku bunga | D6: Risk & Compliance | E6: Regulatory | F6: TRS | G6: ADV - Wholesale Core Services Department | H6: CBS | I6: 2-High | J6: Aktif | K6: 0 | L6: 2 | M6: 0 | N6: 1 | O6: 0 | P6: 3
A7: AMOSAL0007 | B7: Aplikasi Pengundian | C7: Aplikasi undian untuk event/ program pemasaran BNI | D7: Customer Relationship Management | E7: Marketing | F7: CRP | G7: RDL - Customer Care Channel | H7: BOA | I7: 4-Non Critical | J7: Aktif | K7: 0 | L7: 0 | M7: 0 | N7: 1 | O7: 0 | P7: 1
A8: AMOOES0008 | B8: ASP | C8: Aplikasi Perpajakan | D8: Enterprise Support | E8: Finance & Accounting | F8: WPP/WDC | G8: WDL - Integrated Dashboard & Corporate Portal | H8: ???? | I8: 2-High | J8: Aktif | K8: 0 | L8: 2 | M8: 0 | N8: 1 | O8: 0 | P8: 3
A9: AMOOES0009 | B9: Asset Management | C9: Aplikasi untuk mencatat informasi aset tetap, dengan dilengkapi informasi tambahan : foto/gambar asset, nomor proyek, kode anggaran, geo tagging, legalitas, daftar penghuni Gedung/rumah dinas, asuransi dll | D9: Enterprise Support | E9: Facilities Management | F9: PFA | G9: ADV - Enterprise Services Departement | H9: BOA | I9: 3-Moderate | J9: Aktif | K9: 0 | L9: 0 | M9: 1 | N9: 1 | O9: 0 | P9: 2
A10: AFONFO0011 | B10: Autodebet (baru) | C10: Aplikasi berbasis web application untuk mengatur pembayaran tagihan- tagihan mulai dari tagihan listrik, pascabayar, kartu kredit, BPJS, PDAM, layanan | D10: Products & Services | E10: Payment | F10: RDP/RDC | G10: RDL - Customer Care Channel | H10: CBS | I10: 3-Moderate | J10: Aktif | K10: 0 | L10: 0 | M10: 1 | N10: 0 | O10: 1 | P10: 2
A11: AMORAC0012 | B11: Awareness & Supervision Report (ASR) | C11: Aplikasi Awareness & Supervision Report | D11: Risk & Compliance | E11: Internal Audit & Compliance | F11: IAD | G11: ADV - Enterprise Services Departement | H11: BOA | I11: 4-Non Critical | J11: Aktif | K11: 0 | L11: 0 | M11: 0 | N11: 1 | O11: 0 | P11: 1
A12: AMOCSR0013 | B12: Bancassurance Telesaving | C12: pengembangan berdasarkan aktivitas harian yang dilakukan, antara lain : 1. Rekonsil data Nasabah 2. Pendebetan/pembilingan premi 3. Pengembangan premi asuransi 4. Pembayaran no claim bonus | D12: Operational Services | E12: Reconciliation | F12: WEM | G12: RDL - Retail Sales System | H12: BOA | I12: 3-Moderate | J12: Aktif | K12: 0 | L12: 0 | M12: 1 | N12: 1 | O12: 0 | P12: 2
A13: AMOOES0016 | B13: BARS | C13: Account Registry Custody | D13: Products & Services | E13: Custody | F13: BOP | G13: ADV - Wholesale Core Services Department | H13: BOA | I13: 4-Non Critical | J13: Aktif | K13: 0 | L13: 0 | M13: 0 | N13: 1 | O13: 0 | P13: 1
A14: AMOOES0018 | B14: BB Online | C14: Portal untuk reporting sektor BB | D14: #N/A | E14: #N/A | F14: DMA (Data Management Analytic) | G14: DMA (Data Management Analytic) | H14: ???? | I14: 4-Non Critical | J14: Aktif | K14: 0 | L14: 0 | M14: 0 | N14: 1 | O14: 0 | P14: 1
A15: AMORAC0019 | B15: BCP Monitoring (AML System/Regional Compliance Officer) | C15: Aplikasi Monitoring BCP yang ada di Aplikasi AML System | D15: Risk & Compliance | E15: Anti Money Laundering | F15: CMP | G15: ADV - Enterprise Services Departement | H15: BOA | I15: 2-High | J15: Aktif | K15: 0 | L15: 2 | M15: 0 | N15: 1 | O15: 0 | P15: 3
A16: AMODAP0022 | B16: Big Data | C16: Data storage untuk Analytics dan Customer facing application | D16: Enterprise Information System | E16: Big Data | F16: DMA (Data Management Analytic) | G16: DMA (Data Management Analytic) | H16: IDS | I16: 3-Moderate | J16: Aktif | K16: 0 | L16: 0 | M16: 1 | N16: 1 | O16: 0 | P16: 2
A17: AMOCSR0024 | B17: Billing Payment System (BPS) | C17: Rekonsiliasi Bill Payment | D17: Operational Services | E17: Reconciliation | F17: DGO | G17: WDL | H17: BOA | I17: 2-High | J17: Aktif | K17: 1 | L17: 0 | M17: 1 | N17: 1 | O17: 0 | P17: 3
A18: AMORAC0027 | B18: BNI AML (Anti Money Laundering System) | C18: Aplikasi Anti Money Laundering | D18: Risk & Compliance | E18: Anti Money Laundering | F18: CMP | G18: ADV - Enterprise Services Departement | H18: BOA | I18: 2-High | J18: Aktif | K18: 0 | L18: 2 | M18: 0 | N18: 1 | O18: 0 | P18: 3
A19: AFOAFO0029 | B19: BNI Contact Center | C19: Pusat layanan dan complaint handling bagi Nasabah dan Non Nasabah via BNI Call 1500046 utk mendapatkan informasi, melakukan transaksi, dan memperoleh solusi atas permasalahan layanan perbankan. Dan complaint handling utk internal BNI via IT Helpdesk (021 29946000), SAT (021 29926011), dan HCT (021 29946088). | D19: Channels (Bank Channels) | E19: Virtual | F19: CXC | G19: IFM | H19: BOA | I19: 2-High | J19: Aktif | K19: 0 | L19: 0 | M19: 1 | N19: 1 | O19: 1 | P19: 3
A20: AMORAC0030 | B20: BNI Control Overview (BCO) | C20: Aplikasi untuk kontrol internal - Fase I | D20: Risk & Compliance | E20: Operational Risk | F20: IAD | G20: ADV - Enterprise Services Departement | H20: ???? | I20: 4-Non Critical | J20: Aktif | K20: 0 | L20: 0 | M20: 0 | N20: 1 | O20: 0 | P20: 1
A21: AMOOES0031 | B21: BNI Dashboard | C21: Portal untuk reporting sektor BB | D21: Enterprise Information System | E21: Business Intelligence & Analytics | F21: DMA (Data Management Analytic) | G21: DMA (Data Management Analytic) | H21: BOA | I21: 4-Non Critical | J21: Aktif | K21: 0 | L21: 0 | M21: 0 | N21: 1 | O21: 0 | P21: 1
A22: AFONFO0033 | B22: BNIdirect London (LDN) | C22: Global Transaction Banking (GTB) merupakan layanan transaction banking yang disediakan BNI bagi nasabah non perorangan yang ada di luar negeri, menggunakan aplikasi BNI Direct | D22: Channels (Customer Channels) | E22: Wholesale Customer | F22: WPP/WDC | G22: WDL - BNI Direct KCLN | H22: CBS | I22: 3-Moderate | J22: Aktif | M22: 1 | O22: 1 | P22: 2
A23: AFONFO0034 | B23: BNI Experience | C23: Aplikasi berbasis mobile yang berfungsi untuk memberikan informasi lokasi ATM dan Kantor Cabang BNI terdekat dari lokasi/posisi nasabah. | D23: Enterprise Support | E23: Content & Document Management | F23: MCM | G23: RDL - Retail Mobile App | H23: DCP | I23: 4-Non Critical | J23: Aktif | K23: 0 | L23: 0 | M23: 0 | N23: 0 | O23: 1 | P23: 1
A24: AMORAC0035 | B24: BNI for SLIK | C24: Aplikasi penunjang pelaporan Sistem Layanan Informasi Keuangan | D24: Risk & Compliance | E24: Regulatory | F24: CPM, DMA | G24: DMA (Data Management Analytic) | H24: BOA | I24: 3-Moderate | J24: Aktif | K24: 0 | L24: 0 | M24: 0 | N24: 1 | O24: 1 | P24: 2
A25: AMOOES0036 | B25: BNI Forum | C25: Portal media komunikasi internal berbasi Web Intranet untuk menyampaikan informasi berupa berita, panduan transaksi dan operasional juga sebagai media edukasi dan promosi yang terkoneksi ke iCons (Bancslink) | D25: Enterprise Support | E25: Team Collaboration | F25: - | G25: WDL | H25: BOA | I25: 4-Non Critical | J25: Aktif | K25: 0 | L25: 0 | M25: 0 | N25: 1 | O25: 0 | P25: 1
A26: AMOSAL0038 | B26: BNI Move (Digitalisasi KUR) | C26: Sistem onboarding dan pemrosesan pengajuan kredit secara digital yang terintegrasi dengan verifikator debitur | D26: Customer Relationship Management | E26: Sales | F26: CMR | G26: RDL - Retail Sales System | H26: BOA | I26: 3-Moderate | J26: Aktif | K26: 0 | L26: 0 | M26: 1 | N26: 1 | O26: 0 | P26: 2
A27: AFOAFO0039 | B27: BNI Obranch | C27: Aplikasi Pemantauan O-Branch yang bertujuan untuk meningkatkan jangkauan serta akses layanan perbankan kepada masyarakat khususnya pada daerah blank spot atau aksesbilitas terbatas. | D27: Channels (Bank Channels) | E27: Branch | F27: DNS | G27: ADV - Workflow & Automation Fepartment | H27: BOA | I27: 4-Non Critical | J27: Aktif | K27: 0 | L27: 0 | M27: 0 | N27: 1 | O27: 0 | P27: 1
A28: AMOSAL0040 | B28: BNI Poin Plus | C28: Aplikasi yang akan dipakai untuk program loyalti nasabah BNI berbasis teknologi. | D28: Customer Relationship Management | E28: Customer | F28: CRP | G28: RDL - Monitoring & Notification Service | H28: CBS | I28: 3-Moderate | J28: Aktif | K28: 0 | L28: 0 | M28: 0 | N28: 1 | O28: 1 | P28: 2
A29: AFONFO0041 | B29: BNI Simponi | C29: Aplikasi Mobile & Website yang merupakan layanan online DPLK kepada Nasabah (a.l inquiry saldo, monitoring klaim) dan Calon Nasabah (a.l pendaftaran, simulasi) | D29: Channels (Customer Channels) | E29: Retail Customer | F29: PSF | G29: RDL - Retail Mobile App (Simponi Mobile) & RDL - Internet Banking (Simponi Web) | H29: CBS | I29: 3-Moderate | J29: Aktif | K29: 0 | L29: 0 | M29: 0 | N29: 1 | O29: 1 | P29: 2
A30: AMOOES0042 | B30: Branch Navigation | C30: Tools monitoring kinerja dan aktivitas operasional cabang bagi pimpinan. | D30: Operational Services | E30: Reconciliation | F30: DNS | G30: ADV - Workflow & Automation Fepartment | H30: BOA | I30: 4-Non Critical | J30: Aktif | K30: 0 | L30: 0 | M30: 0 | N30: 1 | O30: 0 | P30: 1
A31: AFONFO0044 | B31: Card Derivative Management (CDMA) | C31: Merupakan aplikasi atau sistem berbasis web service dan mobile sebagai sarana bagi Cabang BNI, Mahasiswa, Universitas/Perguruan Tinggi maupun institusi lainnya dalam menyampaikan permohonan order kartu mahasiswa | D31: Channels (Customer Channels) | E31: Wholesale Customer | F31: BOP | G31: RDL - Retail Credit Operation Delivery | H31: BOA | I31: 3-Moderate | J31: Aktif | K31: 0 | L31: 0 | M31: 1 | N31: 1 | O31: 0 | P31: 2
A32: AMOLOM0046 | B32: Credit Bureau Automation System (CBAS) | C32: Credit Bureau Automation System (CBAS) | D32: Operational Services | E32: Loan Operations | F32: RTC | G32: WDL | H32: BOA | I32: 3-Moderate | J32: Aktif | K32: 0 | L32: 0 | M32: 1 | N32: 1 | O32: 0 | P32: 2
A33: AMORAC0048 | B33: CIMS - Compliance Information Management System | C33: Aplikasi Compliance Monitoring System yg terdiri dari : Gratifikasi Online, CIX, Sertifikasi PP, Review PP, Monitoring Denda, AML Report, Kajian PAB, Tindak Lanjut Peraturan | D33: Risk & Compliance | E33: Internal Audit & Compliance | F33: CMP | G33: ADV - Enterprise Services Departement | H33: IDS | I33: 2-High | J33: Aktif | K33: 0 | L33: 2 | M33: 0 | N33: 1 | O33: 0 | P33: 3
A34: AMOLOM0049 | B34: Collateral Data Management System (CDMS) | C34: Portal informasi data jaminan yang ada di BNI, dengan field tambahan yang harus dilengkapi di masing-masing unit. Data jaminan diperoleh dari ICONS | D34: Operational Services | E34: Loan Operations | F34: - | G34: RDL - Retail Credit Operation Delivery | H34: BOA | I34: 3-Moderate | J34: Aktif | K34: 0 | L34: 0 | M34: 1 | N34: 1 | O34: 0 | P34: 2
... A51: AMOSAL0068 | B51: Digisales | C51: Aplikasi penunjang aktivitas Sales | D51: Customer Relationship Management | E51: Sales | F51: SLN | G51: RDL - Retail Sales System | H51: BOA | I51: 2-High | J51: Aktif | K51: 0 | L51: 0 | M51: 1 | N51: 1 | O51: 1 | P51: 3
A52: AFONFO0069 | B52: Digital Invoice | C52: Aplikasi untuk membuat tagihan (invoice) dengan menggunakan metode transfer VA (Virtual Account) | D52: #N/A | E52: #N/A | F52: RDP/RDC | G52: RDL - Transaction & Services | H52: DCP | I52: 3-Moderate | J52: Aktif | K52: 0 | L52: 0 | M52: 0 | N52: 1 | O52: 1 | P52: 2
A53: AFONFO0070 | B53: Digital Platform (Omni Channel) | C53: Penyediaan BNI Digital Platform mencakup besaran Core Services (peningkatan elastisitas performance dan kapabilitas), Omni Channels (integrated & seamless experiences), dan Digital Core (pelengkap kapabilitas dan meningkatkan agility Core Banking). | D53: Channels (Customer Channels) | E53: Retail Customer | F53: RDP/RDC | G53: RDL - Internet Banking | H53: DCP | I53: 3-Moderate | J53: Aktif | K53: 1 | L53: 0 | M53: 1 | N53: 0 | O53: 0 | P53: 2
A54: AMOLOM0071 | B54: Direktori Debitur Ditolak (3D) | C54: Aplikasi untuk monitoring keputusan pengajuan permohonan kredit oleh debitur | D54: Risk & Compliance | E54: Credit Risk | F54: COP | G54: WDL - Relationship Management System | H54: BOA | I54: 2-High | J54: Aktif | K54: 0 | L54: 0 | M54: 1 | N54: 1 | O54: 1 | P54: 3
A55: AMODAP0072 | B55: DNA | C55: Informasi profil dan transaksi nasabah perorangan (nama aplikasi sebelumnya: Exadia) | D55: Enterprise Information System | E55: Data Models Management | F55: DMA (Data Management Analytic) | G55: DMA (Data Management Analytic) | H55: BOA | I55: 4-Non Critical | J55: Aktif | K55: 0 | L55: 0 | M55: 0 | N55: 1 | O55: 0 | P55: 1
A56: ABOLIB0073 | B56: DPLK Accrual | C56: BNI Simponi (Simpanan Pensiun Bank BNI) merupakan Layanan program pensiun yang diselenggarakan oleh Dana Pensiun Lembaga Keuangan PT. Bank Negara Indonesia (Persero) Tbk (DPLK BNI) sejak tahun 1994 berdasarkan Undang-Undang Nomor 11 Tahun 1992 tentang Dana Pensiun. | D56: Products & Services | E56: Pension Management | F56: PSF | G56: ADV - Wholesale Core Services Department | H56: CBS | I56: 3-Moderate | J56: Aktif | K56: 1 | L56: 0 | M56: 0 | N56: 1 | O56: 0 | P56: 2
A57: ABOLIB0074 | B57: DPLK Smile | C57: Aplikasi dana pensiun lembaga keuangan | D57: Products & Services | E57: Pension Management | F57: PSF | G57: ADV - Wholesale Core Services Department | H57: CBS | I57: 3-Moderate | J57: Aktif | K57: 0 | L57: 0 | M57: 1 | N57: 1 | O57: 0 | P57: 2
...

Sheet Automation Monitoring (2)
D1: Last Update 12 Dec 2025 16:25 WIB
B4: Project ID | C4: Application ID | D4: Nama Aplikasi | E4: Estimated / Total TC | F4: Final TC | G4: Done Scripting | I4: Done Running | K4: Timeline Scripting / Regression in Year 2024 | L4: Pdf | M4: Git | N4: Excel | O4: Branch Git | P4: PIC B2B | Q4: PIC FTE | S4: Device | U4: Chart | AL4: Nama Aplikasi | AM4: Estimated / Total TC | AN4: Final TC | AO4: Done Scripting | AQ4: Done Running | AT4: Nama Aplikasi | AU4: Estimated / Total TC | AV4: Final TC | AW4: Done Scripting | AY4: Done Running | BB4: Nama Aplikasi | BC4: Estimated / Total TC | BD4: Final TC | BE4: Done Scripting | BG4: Done Running
G5: TC | H5: Percentage | I5: TC | J5: Percentage | R5: Tools Auto | AO5: TC | AP5: Percentage | AQ5: TC | AR5: Percentage | AW5: TC | AX5: Percentage | AY5: TC | AZ5: Percentage | BE5: TC | BF5: Percentage | BG5: TC | BH5: Percentage
B6: P23055 | C6: ABOAST0135 | D6: Integrated & Centralized Online System (ICONS)-Poseidon | E6: =BC6 -> 1567 | F6: =BD6 -> 1554 | G6: =BE6 -> 1416 | H6: =G6/F6 -> 0.91119691 | I6: =BG6 -> 1416 | J6: =I6/F6 -> 0.91119691 | K6: Jan | M6: https://gitlab-dc.bni.co.id/marchy.tio/icons.git | O6: dev_alternity_merging | R6: UFT​ | AL6: Tiplus UFE | AM6: 299 | AN6: 252 | AO6: 252 | AP6: =AO6/AN6 -> 1 | AQ6: 252 | AR6: =AQ6/AN6 -> 1 | AT6: Ibank Remittance Fase 2 | AU6: 481 | AV6: 457 | AW6: 457 | AX6: =AW6/AV6 -> 1 | AY6: 457 | AZ6: =AY6/AV6 -> 1 | BB6: ICONS Poseidon | BC6: 1567 | BD6: 1554 | BE6: 1416 | BF6: =BE6/BD6 -> 0.91119691 | BG6: 1416 | BH6: =BG6/BD6 -> 0.91119691
B7: A24001 | C7: AFONFO0229 | D7: SMS Banking-Mobile SMS Menu (Android) | E7: 898 | F7: 780 | G7: 772 | H7: =G7/F7 -> 0.98974359 | I7: 772 | J7: =I7/F7 -> 0.98974359 | K7: Oct-Nov | L7: https://bankbnitbk.sharepoint.com/:f:/s/TEST212/EkBwukLUexlCvNbiS9xVLOwBec_4sO1J5vspDybADFMf8g?e=YPNGbQ | M7: https://gitlab-dc.bni.co.id/coe-duplicate/test-automation/katalon-sms-menu-android.git | P7: Alvin | Q7: Mbincar | R7: Katalon​ | AL7: Mobile Agen46 (iOS) | AM7: 712 | AN7: 306 | AO7: 306 | AP7: =AO7/AN7 -> 1 | AQ7: 306 | AR7: =AQ7/AN7 -> 1 | AT7: LMS Sprint 2 | AU7: 16 | AV7: 16 | AW7: 16 | AX7: =AW7/AV7 -> 1 | AY7: 16 | AZ7: =AY7/AV7 -> 1 | BC7: Tiplus UFE | BD7: Digisales APK Generalis dan FTE
B8: A24001 | C8: AFONFO0229 | D8: SMS Banking-Mobile SMS Menu (iOS) | E8: 898 | F8: 780 | G8: 772 | H8: =G8/F8 -> 0.98974359 | I8: 772 | J8: =I8/F8 -> 0.98974359 | K8: Oct-Nov | L8: https://bankbnitbk.sharepoint.com/:f:/s/TEST212/EsU0M1xMRx9PokMQJ0xEYqoBFapR-d2DAIfXACNcm1GImQ?e=Td26y3 | M8: https://gitlab-dc.bni.co.id/coe-duplicate/test-automation/katalon-sms-menu-ios.git | P8: Alvin | Q8: Mbincar | R8: Katalon​ | V8: Stop / Aplikasi sudah tidak dilanjutkan scripting / Service Down | AL8: Mobile Credit Card (Android) | AM8: 75 | AN8: 60 | AO8: 40 | AP8: =AO8/AN8 -> 0.66666667 | AQ8: 40 | AR8: =AQ8/AN8 -> 0.66666667 | AT8: LMS Sprint 3 | AU8: 37 | AV8: 37 | AW8: 37 | AX8: =AW8/AV8 -> 1 | AY8: 37 | AZ8: =AY8/AW8 -> 1 | BC8: BNI Direct Lite | BD8: Digisales Browser Generalis dan FTE
B9: P23094 | C9: AMOOES0309 | D9: DigIMS | E9: 1153 | F9: 1137 | G9: 590 | H9: =G9/F9 -> 0.51890941 | I9: 583 | J9: =I9/F9 -> 0.51275286 | K9: Oct-Nov | L9: https://bankbnitbk.sharepoint.com/:f:/s/TEST212/EmDQeI6wuE9Erk-8RtI6KBsBdR4mp5abwD8GJYpgrlXEyA?e=FOsV8R | M9: https://gitlab-dc.bni.co.id/coe-duplicate/test-automation/katalon-digims.git | P9: Alkha | Q9: Thomas | R9: Katalon​ | U9: 3 hari | V9: 20 tc | W9: 35 hari/ 1 bulan 2 minggu | AL9: Smart VA Portal | AM9: 669 | AN9: 669 | AO9: 157 | AP9: =AO9/AN9 -> 0.23467862 | AQ9: 157 | AR9: =AQ9/AN9 -> 0.23467862
B10: P24091 | C10: AMOSAL0068 | D10: Digisales-Portal (4B) | E10: 60 | F10: 47 | G10: 47 | H10: =G10/F10 -> 1 | I10: 47 | J10: =I10/F10 -> 1 | K10: Oct-Nov | L10: https://bankbnitbk.sharepoint.com/:f:/s/TEST212/EpwQ_mowTgRIsBNX-yqk1SsBydKz148dpodB8gftHbFBaw?e=24HPLd | M10: https://gitlab-dc.bni.co.id/coe-duplicate/test-automation/katalon-digisales-portal.git | R10: Katalon​ | U10: 3 hari | V10: 20 tc | AL10: Cash Management Lite | AM10: 29603 | AN10: 29603 | AO10: 28 | AP10: =AO10/AN10 -> 0.00094585008 | AQ10: 18 | AR10: =AQ10/AN10 -> 0.00060804648
B11: P24091 | C11: AMOSAL0068 | D11: Digisales-Generalis Mobile Browser (4B) | E11: 49 | F11: 47 | G11: 47 | H11: =G11/F11 -> 1 | I11: 47 | J11: =I11/F11 -> 1 | K11: Oct-Nov | L11: https://bankbnitbk.sharepoint.com/:f:/s/TEST212/ElybKHNWvkxDjZztpmaLLWUBbK7bk4AXKBTpXRbjFe-LvQ?e=zw4Rt1 | M11: https://gitlab-dc.bni.co.id/coe-duplicate/test-automation/katalon-digisales-generalis-mobile-browser.git | R11: Katalon​ | U11: 3 hari | V11: 20 tc | AL11: GB Online | AM11: 555 | AN11: 420 | AO11: 0 | AP11: =AO11/AN11 -> 0 | AQ11: 0 | AR11: =AQ11/AN11 -> 0
B12: P24091 | C12: AMOSAL0068 | D12: Digisales-Generalis Mobile APK (4B) | E12: 49 | F12: 47 | G12: 47 | H12: =G12/F12 -> 1 | I12: 47 | J12: =I12/F12 -> 1 | K12: Oct-Nov | L12: https://bankbnitbk.sharepoint.com/:f:/s/TEST212/ElM4wgKu4IpEo1aN26W6_xEBbG1DgM8lJCMGlpG4MzZ0Mg?e=ugHmtA | M12: https://gitlab-dc.bni.co.id/coe-duplicate/test-automation/katalon-digisales-generalis-mobile-apk.git | P12: Unedo | R12: Katalon​ | U12: 13 hari | V12: 20 tc
B13: P24091 | C13: AMOSAL0068 | D13: Digisales-FTE Mobile Browser (4B) | E13: 257 | F13: 257 | G13: 257 | H13: =G13/F13 -> 1 | I13: 249 | J13: =I13/F13 -> 0.9688716 | K13: Nov-Dec | L13: https://bankbnitbk.sharepoint.com/:f:/s/TEST212/Eup95DJS-rFLljrtCvblvq0BOzTzM9ulTTYDds9KCmcULw?e=eHpNAF | M13: https://gitlab-dc.bni.co.id/coe-duplicate/test-automation/katalon-digisales-fte-mobile-browser.git | R13: Katalon​ | U13: 13 hari | V13: 20 tc
B14: P24091 | C14: AMOSAL0068 | D14: Digisales-FTE Mobile APK (4B) | E14: 257 | F14: 257 | G14: 257 | H14: =G14/F14 -> 1 | I14: 254 | J14: =I14/F14 -> 0.98832685 | K14: Nov-Dec | L14: https://bankbnitbk.sharepoint.com/:f:/s/TEST212/EvzzQSkZgHtIo46EbcwpAKUBVU-0l60enMgmHRDjNWBkbQ?e=k341oe | M14: https://gitlab-dc.bni.co.id/coe-duplicate/test-automation/katalon-digisales-fte-mobile-apk.git | P14: Unedo | R14: Katalon​ | U14: 264 hari / 12 bulan | V14: 20 tc | X14: > | Y14: 88 hari / 4 bulan | Z14: asumsi 3 resource
B15: P24019 | C15: AMOCSR0273 | D15: Smart VA-Portal | E15: 669 | F15: 629 | G15: 629 | H15: =G15/F15 -> 1 | I15: 629 | J15: =I15/F15 -> 1 | K15: Dec-Jan | L15: https://bankbnitbk.sharepoint.com/:f:/s/TEST212/EsE_n7BKP49DtZV_DeXugQcBATb7DB5RJ5f3NFGwOL9xhw?e=0F4t6H | M15: https://gitlab.bni.co.id/coe-duplicate/test-automation/katalon-smartva-portal | P15: Alkha, Akbar | Q15: Thomas | R15: Katalon​
B16: P23003 | C16: AMOMWI0004 | D16: API Management-API Gateway | E16: 660 | F16: 658 | G16: 658 | H16: =G16/F16 -> 1 | I16: 658 | J16: =I16/F16 -> 1 | K16: Jan-Oct | L16: https://bankbnitbk.sharepoint.com/:f:/s/TEST212/EkHylvVI_-NHkreXGOrLvDgBuEj6fKPO3ktyu_-69pu-nA?e=EVyUWF | M16: https://gitlab-dc.bni.co.id/coe-duplicate/test-automation/katalon-bni-api-gateway.git | P16: Alkha, Andin | Q16: Thomas | R16: Katalon​
